2018-04-02 10:08:29 WARNING (Recorder) [homeassistant.components.recorder] Ended unfinished session (id=47 from 2018-03-20 01:00:37.124313)
2018-04-02 10:08:32 ERROR (MainThread) [homeassistant.components.media_player] Error on device update!
Traceback (most recent call last):
  File "/srv/homeassistant/lib/python3.5/site-packages/urllib3/connection.py", line 141, in _new_conn
    (self.host, self.port), self.timeout, **extra_kw)
  File "/srv/homeassistant/lib/python3.5/site-packages/urllib3/util/connection.py", line 60, in create_connection
    for res in socket.getaddrinfo(host, port, family, socket.SOCK_STREAM):
  File "/usr/lib/python3.5/socket.py", line 732, in getaddrinfo
    for res in _socket.getaddrinfo(host, port, family, type, proto, flags):
socket.gaierror: [Errno -3] Temporary failure in name resolution

During handling of the above exception, another exception occurred:

Traceback (most recent call last):
  File "/srv/homeassistant/lib/python3.5/site-packages/urllib3/connectionpool.py", line 601, in urlopen
    chunked=chunked)
  File "/srv/homeassistant/lib/python3.5/site-packages/urllib3/connectionpool.py", line 346, in _make_request
    self._validate_conn(conn)
  File "/srv/homeassistant/lib/python3.5/site-packages/urllib3/connectionpool.py", line 850, in _validate_conn
    conn.connect()
  File "/srv/homeassistant/lib/python3.5/site-packages/urllib3/connection.py", line 284, in connect
    conn = self._new_conn()
  File "/srv/homeassistant/lib/python3.5/site-packages/urllib3/connection.py", line 150, in _new_conn
    self, "Failed to establish a new connection: %s" % e)
urllib3.exceptions.NewConnectionError: <urllib3.connection.VerifiedHTTPSConnection object at 0xb1bab66c>: Failed to establish a new connection: [Errno -3] Temporary failure in name resolution

During handling of the above exception, another exception occurred:

Traceback (most recent call last):
  File "/srv/homeassistant/lib/python3.5/site-packages/requests/adapters.py", line 440, in send
    timeout=timeout
  File "/srv/homeassistant/lib/python3.5/site-packages/urllib3/connectionpool.py", line 639, in urlopen
    _stacktrace=sys.exc_info()[2])
  File "/srv/homeassistant/lib/python3.5/site-packages/urllib3/util/retry.py", line 388, in increment
    raise MaxRetryError(_pool, url, error or ResponseError(cause))
urllib3.exceptions.MaxRetryError: HTTPSConnectionPool(host='accounts.spotify.com', port=443): Max retries exceeded with url: /api/token (Caused by NewConnectionError('<urllib3.connection.VerifiedHTTPSConnection object at 0xb1bab66c>: Failed to establish a new connection: [Errno -3] Temporary failure in name resolution',))

During handling of the above exception, another exception occurred:

Traceback (most recent call last):
  File "/srv/homeassistant/lib/python3.5/site-packages/homeassistant/helpers/entity_component.py", line 217, in async_add_entity
    yield from entity.async_device_update(warning=False)
  File "/srv/homeassistant/lib/python3.5/site-packages/homeassistant/helpers/entity.py", line 306, in async_device_update
    yield from self.hass.async_add_job(self.update)
  File "/usr/lib/python3.5/asyncio/futures.py", line 361, in __iter__
    yield self  # This tells Task to wait for completion.
  File "/usr/lib/python3.5/asyncio/tasks.py", line 296, in _wakeup
    future.result()
  File "/usr/lib/python3.5/asyncio/futures.py", line 274, in result
    raise self._exception
  File "/usr/lib/python3.5/concurrent/futures/thread.py", line 55, in run
    result = self.fn(*self.args, **self.kwargs)
  File "/srv/homeassistant/lib/python3.5/site-packages/homeassistant/components/media_player/spotify.py", line 164, in update
    self.refresh_spotify_instance()
  File "/srv/homeassistant/lib/python3.5/site-packages/homeassistant/components/media_player/spotify.py", line 150, in refresh_spotify_instance
    self._token_info['refresh_token'])
  File "/srv/homeassistant/lib/python3.5/site-packages/spotipy/oauth2.py", line 239, in refresh_access_token
    headers=headers, proxies=self.proxies)
  File "/srv/homeassistant/lib/python3.5/site-packages/requests/api.py", line 112, in post
    return request('post', url, data=data, json=json, **kwargs)
  File "/srv/homeassistant/lib/python3.5/site-packages/requests/api.py", line 58, in request
    return session.request(method=method, url=url, **kwargs)
  File "/srv/homeassistant/lib/python3.5/site-packages/requests/sessions.py", line 508, in request
    resp = self.send(prep, **send_kwargs)
  File "/srv/homeassistant/lib/python3.5/site-packages/requests/sessions.py", line 618, in send
    r = adapter.send(request, **kwargs)
  File "/srv/homeassistant/lib/python3.5/site-packages/requests/adapters.py", line 508, in send
    raise ConnectionError(e, request=request)
requests.exceptions.ConnectionError: HTTPSConnectionPool(host='accounts.spotify.com', port=443): Max retries exceeded with url: /api/token (Caused by NewConnectionError('<urllib3.connection.VerifiedHTTPSConnection object at 0xb1bab66c>: Failed to establish a new connection: [Errno -3] Temporary failure in name resolution',))
2018-04-02 10:08:40 ERROR (MainThread) [homeassistant.core] Error doing job: Task exception was never retrieved
Traceback (most recent call last):
  File "/usr/lib/python3.5/asyncio/tasks.py", line 241, in _step
    result = coro.throw(exc)
  File "/srv/homeassistant/lib/python3.5/site-packages/homeassistant/components/discovery.py", line 127, in scan_devices
    results = yield from hass.async_add_job(_discover, netdisco)
  File "/usr/lib/python3.5/asyncio/futures.py", line 361, in __iter__
    yield self  # This tells Task to wait for completion.
  File "/usr/lib/python3.5/asyncio/tasks.py", line 296, in _wakeup
    future.result()
  File "/usr/lib/python3.5/asyncio/futures.py", line 274, in result
    raise self._exception
  File "/usr/lib/python3.5/concurrent/futures/thread.py", line 55, in run
    result = self.fn(*self.args, **self.kwargs)
  File "/srv/homeassistant/lib/python3.5/site-packages/homeassistant/components/discovery.py", line 153, in _discover
    netdisco.scan()
  File "/srv/homeassistant/lib/python3.5/site-packages/netdisco/discovery.py", line 60, in scan
    self.gdm.scan()
  File "/srv/homeassistant/lib/python3.5/site-packages/netdisco/gdm.py", line 22, in scan
    self.update()
  File "/srv/homeassistant/lib/python3.5/site-packages/netdisco/gdm.py", line 77, in update
    sock.sendto(gdm_msg, (gdm_ip, gdm_port))
OSError: [Errno 101] Network is unreachable
2018-04-02 11:08:31 ERROR (MainThread) [homeassistant.components.updater] Could not contact Home Assistant Update to check for updates
2018-04-02 11:54:57 ERROR (MainThread) [homeassistant.core] Invalid service data for light.turn_on: expected int for dictionary value @ data['brightness']. Got ''
2018-04-02 12:20:40 ERROR (MainThread) [homeassistant.core] Invalid service data for light.turn_on: expected int for dictionary value @ data['brightness']. Got ''
2018-04-02 13:45:11 ERROR (MainThread) [homeassistant.core] Invalid service data for light.turn_on: expected int for dictionary value @ data['brightness']. Got ''
2018-04-02 17:08:02 ERROR (MainThread) [homeassistant.core] Invalid service data for light.turn_on: expected int for dictionary value @ data['brightness']. Got ''
2018-04-02 17:14:26 ERROR (MainThread) [homeassistant.core] Invalid service data for light.turn_on: expected int for dictionary value @ data['brightness']. Got ''
2018-04-02 19:46:09 ERROR (MainThread) [homeassistant.core] Invalid service data for light.turn_on: expected int for dictionary value @ data['brightness']. Got ''
2018-04-02 20:41:31 ERROR (MainThread) [homeassistant.core] Invalid service data for light.turn_on: expected int for dictionary value @ data['brightness']. Got ''
2018-04-02 21:49:29 ERROR (MainThread) [homeassistant.core] Invalid service data for light.turn_on: expected int for dictionary value @ data['brightness']. Got ''
2018-04-03 07:16:49 ERROR (MainThread) [homeassistant.core] Invalid service data for light.turn_on: expected int for dictionary value @ data['brightness']. Got ''
2018-04-03 07:19:37 ERROR (MainThread) [homeassistant.core] Invalid service data for light.turn_on: expected int for dictionary value @ data['brightness']. Got ''
2018-04-03 08:15:33 ERROR (MainThread) [homeassistant.core] Invalid service data for light.turn_on: expected int for dictionary value @ data['brightness']. Got ''
2018-04-03 08:43:49 ERROR (MainThread) [homeassistant.core] Invalid service data for light.turn_on: expected int for dictionary value @ data['brightness']. Got ''
2018-04-03 08:58:46 ERROR (MainThread) [homeassistant.core] Invalid service data for light.turn_on: expected int for dictionary value @ data['brightness']. Got ''
2018-04-03 09:43:27 ERROR (MainThread) [homeassistant.core] Invalid service data for light.turn_on: expected int for dictionary value @ data['brightness']. Got ''
2018-04-03 09:59:19 ERROR (MainThread) [homeassistant.core] Invalid service data for light.turn_on: expected int for dictionary value @ data['brightness']. Got ''
2018-04-03 10:42:15 ERROR (MainThread) [homeassistant.core] Invalid service data for light.turn_on: expected int for dictionary value @ data['brightness']. Got ''
2018-04-03 10:43:05 ERROR (MainThread) [homeassistant.core] Invalid service data for light.turn_on: expected int for dictionary value @ data['brightness']. Got ''
2018-04-03 13:13:01 ERROR (MainThread) [homeassistant.core] Invalid service data for light.turn_on: expected int for dictionary value @ data['brightness']. Got ''
2018-04-03 13:14:20 ERROR (MainThread) [homeassistant.core] Invalid service data for light.turn_on: expected int for dictionary value @ data['brightness']. Got ''
2018-04-03 13:38:23 ERROR (MainThread) [homeassistant.core] Invalid service data for light.turn_on: expected int for dictionary value @ data['brightness']. Got ''
2018-04-03 14:14:45 ERROR (MainThread) [homeassistant.core] Invalid service data for light.turn_on: expected int for dictionary value @ data['brightness']. Got ''
2018-04-03 16:13:52 ERROR (MainThread) [homeassistant.core] Invalid service data for light.turn_on: expected int for dictionary value @ data['brightness']. Got ''
2018-04-03 18:48:21 ERROR (MainThread) [homeassistant.core] Invalid service data for light.turn_on: expected int for dictionary value @ data['brightness']. Got ''
2018-04-03 18:52:14 ERROR (MainThread) [homeassistant.core] Invalid service data for light.turn_on: expected int for dictionary value @ data['brightness']. Got ''
2018-04-03 20:09:52 ERROR (MainThread) [homeassistant.core] Invalid service data for light.turn_on: expected int for dictionary value @ data['brightness']. Got ''
2018-04-04 07:00:58 ERROR (MainThread) [homeassistant.core] Invalid service data for light.turn_on: expected int for dictionary value @ data['brightness']. Got ''
2018-04-04 07:14:36 ERROR (MainThread) [homeassistant.core] Invalid service data for light.turn_on: expected int for dictionary value @ data['brightness']. Got ''
2018-04-04 08:55:57 ERROR (MainThread) [homeassistant.core] Invalid service data for light.turn_on: expected int for dictionary value @ data['brightness']. Got ''
2018-04-04 10:12:40 ERROR (MainThread) [homeassistant.core] Invalid service data for light.turn_on: expected int for dictionary value @ data['brightness']. Got ''
2018-04-04 11:03:32 ERROR (MainThread) [homeassistant.core] Invalid service data for light.turn_on: expected int for dictionary value @ data['brightness']. Got ''
2018-04-04 11:08:36 ERROR (MainThread) [homeassistant.components.updater] Could not contact Home Assistant Update to check for updates
2018-04-04 11:26:56 ERROR (MainThread) [homeassistant.core] Invalid service data for light.turn_on: expected int for dictionary value @ data['brightness']. Got ''
2018-04-04 13:00:55 ERROR (MainThread) [homeassistant.core] Invalid service data for light.turn_on: expected int for dictionary value @ data['brightness']. Got ''
2018-04-04 13:12:37 ERROR (MainThread) [homeassistant.core] Invalid service data for light.turn_on: expected int for dictionary value @ data['brightness']. Got ''
2018-04-04 13:51:11 ERROR (MainThread) [homeassistant.core] Invalid service data for light.turn_on: expected int for dictionary value @ data['brightness']. Got ''
2018-04-04 14:18:50 ERROR (MainThread) [homeassistant.core] Invalid service data for light.turn_on: expected int for dictionary value @ data['brightness']. Got ''
2018-04-04 17:50:02 ERROR (MainThread) [homeassistant.core] Invalid service data for light.turn_on: expected int for dictionary value @ data['brightness']. Got ''
2018-04-04 20:00:11 ERROR (MainThread) [homeassistant.core] Invalid service data for light.turn_on: expected int for dictionary value @ data['brightness']. Got ''
2018-04-04 20:29:39 ERROR (MainThread) [homeassistant.core] Invalid service data for light.turn_on: expected int for dictionary value @ data['brightness']. Got ''
2018-04-04 21:01:39 ERROR (MainThread) [homeassistant.core] Invalid service data for light.turn_on: expected int for dictionary value @ data['brightness']. Got ''
2018-04-05 07:27:33 ERROR (MainThread) [homeassistant.core] Invalid service data for light.turn_on: expected int for dictionary value @ data['brightness']. Got ''
2018-04-05 07:59:48 ERROR (MainThread) [homeassistant.core] Invalid service data for light.turn_on: expected int for dictionary value @ data['brightness']. Got ''
2018-04-05 08:23:43 ERROR (MainThread) [homeassistant.core] Invalid service data for light.turn_on: expected int for dictionary value @ data['brightness']. Got ''
2018-04-05 08:50:35 ERROR (MainThread) [homeassistant.core] Invalid service data for light.turn_on: expected int for dictionary value @ data['brightness']. Got ''
2018-04-05 09:30:27 ERROR (MainThread) [homeassistant.core] Invalid service data for light.turn_on: expected int for dictionary value @ data['brightness']. Got ''
2018-04-05 14:06:15 ERROR (MainThread) [homeassistant.core] Invalid service data for light.turn_on: expected int for dictionary value @ data['brightness']. Got ''
2018-04-05 14:07:27 ERROR (MainThread) [homeassistant.core] Invalid service data for light.turn_on: expected int for dictionary value @ data['brightness']. Got ''
2018-04-05 14:20:00 ERROR (MainThread) [homeassistant.core] Invalid service data for light.turn_on: expected int for dictionary value @ data['brightness']. Got ''
2018-04-05 14:23:27 ERROR (MainThread) [homeassistant.core] Invalid service data for light.turn_on: expected int for dictionary value @ data['brightness']. Got ''
2018-04-05 16:23:55 ERROR (MainThread) [homeassistant.core] Invalid service data for light.turn_on: expected int for dictionary value @ data['brightness']. Got ''
2018-04-05 16:38:37 ERROR (MainThread) [homeassistant.core] Invalid service data for light.turn_on: expected int for dictionary value @ data['brightness']. Got ''
2018-04-05 18:53:01 ERROR (MainThread) [homeassistant.core] Invalid service data for light.turn_on: expected int for dictionary value @ data['brightness']. Got ''
2018-04-05 18:53:48 ERROR (MainThread) [homeassistant.core] Invalid service data for light.turn_on: expected int for dictionary value @ data['brightness']. Got ''
2018-04-05 19:16:04 ERROR (MainThread) [homeassistant.core] Invalid service data for light.turn_on: expected int for dictionary value @ data['brightness']. Got ''
2018-04-05 19:21:55 ERROR (MainThread) [homeassistant.core] Invalid service data for light.turn_on: expected int for dictionary value @ data['brightness']. Got ''
2018-04-05 20:09:30 ERROR (MainThread) [homeassistant.core] Invalid service data for light.turn_on: expected int for dictionary value @ data['brightness']. Got ''
2018-04-05 20:24:49 ERROR (MainThread) [homeassistant.core] Invalid service data for light.turn_on: expected int for dictionary value @ data['brightness']. Got ''
2018-04-05 20:36:56 ERROR (MainThread) [homeassistant.core] Invalid service data for light.turn_on: expected int for dictionary value @ data['brightness']. Got ''
2018-04-05 20:40:18 ERROR (MainThread) [homeassistant.core] Invalid service data for light.turn_on: expected int for dictionary value @ data['brightness']. Got ''
2018-04-06 07:19:50 ERROR (MainThread) [homeassistant.core] Invalid service data for light.turn_on: expected int for dictionary value @ data['brightness']. Got ''
2018-04-06 08:01:27 ERROR (MainThread) [homeassistant.core] Invalid service data for light.turn_on: expected int for dictionary value @ data['brightness']. Got ''
2018-04-06 09:07:13 ERROR (MainThread) [homeassistant.core] Invalid service data for light.turn_on: expected int for dictionary value @ data['brightness']. Got ''
2018-04-06 14:21:13 ERROR (MainThread) [homeassistant.core] Invalid service data for light.turn_on: expected int for dictionary value @ data['brightness']. Got ''
2018-04-06 16:05:18 ERROR (MainThread) [homeassistant.core] Invalid service data for light.turn_on: expected int for dictionary value @ data['brightness']. Got ''
2018-04-06 20:42:57 ERROR (MainThread) [homeassistant.core] Invalid service data for light.turn_on: expected int for dictionary value @ data['brightness']. Got ''
2018-04-07 07:19:31 ERROR (MainThread) [homeassistant.core] Invalid service data for light.turn_on: expected int for dictionary value @ data['brightness']. Got ''
2018-04-07 07:55:48 ERROR (MainThread) [homeassistant.core] Invalid service data for light.turn_on: expected int for dictionary value @ data['brightness']. Got ''
2018-04-07 10:00:29 ERROR (MainThread) [homeassistant.core] Invalid service data for light.turn_on: expected int for dictionary value @ data['brightness']. Got ''
2018-04-07 10:12:58 ERROR (MainThread) [homeassistant.core] Invalid service data for light.turn_on: expected int for dictionary value @ data['brightness']. Got ''
2018-04-07 11:36:46 ERROR (MainThread) [homeassistant.core] Invalid service data for light.turn_on: expected int for dictionary value @ data['brightness']. Got ''
2018-04-07 13:14:39 ERROR (MainThread) [homeassistant.core] Invalid service data for light.turn_on: expected int for dictionary value @ data['brightness']. Got ''
2018-04-07 13:33:44 ERROR (MainThread) [homeassistant.core] Invalid service data for light.turn_on: expected int for dictionary value @ data['brightness']. Got ''
2018-04-07 13:52:14 ERROR (MainThread) [homeassistant.core] Invalid service data for light.turn_on: expected int for dictionary value @ data['brightness']. Got ''
2018-04-07 14:39:31 ERROR (MainThread) [homeassistant.core] Invalid service data for light.turn_on: expected int for dictionary value @ data['brightness']. Got ''
2018-04-07 15:06:05 ERROR (MainThread) [homeassistant.core] Invalid service data for light.turn_on: expected int for dictionary value @ data['brightness']. Got ''
2018-04-07 15:10:20 ERROR (MainThread) [homeassistant.core] Invalid service data for light.turn_on: expected int for dictionary value @ data['brightness']. Got ''
2018-04-07 15:13:54 ERROR (MainThread) [homeassistant.core] Invalid service data for light.turn_on: expected int for dictionary value @ data['brightness']. Got ''
2018-04-07 15:16:20 ERROR (MainThread) [homeassistant.core] Invalid service data for light.turn_on: expected int for dictionary value @ data['brightness']. Got ''
2018-04-07 15:20:51 ERROR (MainThread) [homeassistant.core] Invalid service data for light.turn_on: expected int for dictionary value @ data['brightness']. Got ''
2018-04-08 08:00:06 ERROR (MainThread) [homeassistant.core] Invalid service data for light.turn_on: expected int for dictionary value @ data['brightness']. Got ''
2018-04-08 08:31:02 ERROR (MainThread) [homeassistant.core] Invalid service data for light.turn_on: expected int for dictionary value @ data['brightness']. Got ''
2018-04-08 11:28:49 ERROR (MainThread) [homeassistant.core] Invalid service data for light.turn_on: expected int for dictionary value @ data['brightness']. Got ''
2018-04-08 11:45:14 ERROR (MainThread) [homeassistant.core] Invalid service data for light.turn_on: expected int for dictionary value @ data['brightness']. Got ''
2018-04-08 11:45:47 ERROR (MainThread) [homeassistant.core] Invalid service data for light.turn_on: expected int for dictionary value @ data['brightness']. Got ''
2018-04-08 13:28:19 ERROR (MainThread) [homeassistant.core] Invalid service data for light.turn_on: expected int for dictionary value @ data['brightness']. Got ''
2018-04-08 14:29:53 ERROR (MainThread) [homeassistant.core] Invalid service data for light.turn_on: expected int for dictionary value @ data['brightness']. Got ''
2018-04-08 15:57:43 ERROR (MainThread) [homeassistant.core] Invalid service data for light.turn_on: expected int for dictionary value @ data['brightness']. Got ''
2018-04-08 18:00:08 ERROR (MainThread) [homeassistant.core] Invalid service data for light.turn_on: expected int for dictionary value @ data['brightness']. Got ''
2018-04-08 19:03:36 ERROR (MainThread) [homeassistant.core] Invalid service data for light.turn_on: expected int for dictionary value @ data['brightness']. Got ''
2018-04-08 19:07:26 ERROR (MainThread) [homeassistant.core] Invalid service data for light.turn_on: expected int for dictionary value @ data['brightness']. Got ''
2018-04-08 19:20:40 ERROR (MainThread) [homeassistant.core] Invalid service data for light.turn_on: expected int for dictionary value @ data['brightness']. Got ''
2018-04-08 20:30:58 ERROR (MainThread) [homeassistant.core] Invalid service data for light.turn_on: expected int for dictionary value @ data['brightness']. Got ''
2018-04-08 21:44:50 ERROR (MainThread) [homeassistant.core] Timer got out of sync. Resetting
